{
 "cells": [
  {
   "cell_type": "code",
   "execution_count": 1,
   "metadata": {},
   "outputs": [
    {
     "name": "stderr",
     "output_type": "stream",
     "text": [
      "Using TensorFlow backend.\n",
      "ERROR:root:Internal Python error in the inspect module.\n",
      "Below is the traceback from this internal error.\n",
      "\n",
      "ERROR:root:Internal Python error in the inspect module.\n",
      "Below is the traceback from this internal error.\n",
      "\n",
      "ERROR:root:Internal Python error in the inspect module.\n",
      "Below is the traceback from this internal error.\n",
      "\n"
     ]
    },
    {
     "name": "stdout",
     "output_type": "stream",
     "text": [
      "Traceback (most recent call last):\n",
      "  File \"c:\\Users\\FRED031\\.conda\\envs\\tf-gpu\\lib\\site-packages\\IPython\\core\\interactiveshell.py\", line 3552, in run_code\n",
      "    exec(code_obj, self.user_global_ns, self.user_ns)\n",
      "  File \"C:\\Users\\FRED031\\AppData\\Local\\Temp\\ipykernel_22632\\2531087222.py\", line 9, in <module>\n",
      "    import matplotlib.pyplot as plt\n",
      "ModuleNotFoundError: No module named 'matplotlib'\n",
      "\n",
      "During handling of the above exception, another exception occurred:\n",
      "\n",
      "Traceback (most recent call last):\n",
      "  File \"c:\\Users\\FRED031\\.conda\\envs\\tf-gpu\\lib\\site-packages\\IPython\\core\\interactiveshell.py\", line 2098, in showtraceback\n",
      "    stb = value._render_traceback_()\n",
      "AttributeError: 'ModuleNotFoundError' object has no attribute '_render_traceback_'\n",
      "\n",
      "During handling of the above exception, another exception occurred:\n",
      "\n",
      "Traceback (most recent call last):\n",
      "  File \"c:\\Users\\FRED031\\.conda\\envs\\tf-gpu\\lib\\site-packages\\IPython\\core\\ultratb.py\", line 1101, in get_records\n",
      "    return _fixed_getinnerframes(etb, number_of_lines_of_context, tb_offset)\n",
      "  File \"c:\\Users\\FRED031\\.conda\\envs\\tf-gpu\\lib\\site-packages\\IPython\\core\\ultratb.py\", line 248, in wrapped\n",
      "    return f(*args, **kwargs)\n",
      "  File \"c:\\Users\\FRED031\\.conda\\envs\\tf-gpu\\lib\\site-packages\\IPython\\core\\ultratb.py\", line 281, in _fixed_getinnerframes\n",
      "    records = fix_frame_records_filenames(inspect.getinnerframes(etb, context))\n",
      "  File \"c:\\Users\\FRED031\\.conda\\envs\\tf-gpu\\lib\\inspect.py\", line 1502, in getinnerframes\n",
      "    frameinfo = (tb.tb_frame,) + getframeinfo(tb, context)\n",
      "  File \"c:\\Users\\FRED031\\.conda\\envs\\tf-gpu\\lib\\inspect.py\", line 1460, in getframeinfo\n",
      "    filename = getsourcefile(frame) or getfile(frame)\n",
      "  File \"c:\\Users\\FRED031\\.conda\\envs\\tf-gpu\\lib\\inspect.py\", line 696, in getsourcefile\n",
      "    if getattr(getmodule(object, filename), '__loader__', None) is not None:\n",
      "  File \"c:\\Users\\FRED031\\.conda\\envs\\tf-gpu\\lib\\inspect.py\", line 733, in getmodule\n",
      "    if ismodule(module) and hasattr(module, '__file__'):\n",
      "  File \"c:\\Users\\FRED031\\.conda\\envs\\tf-gpu\\lib\\site-packages\\tensorflow\\__init__.py\", line 50, in __getattr__\n",
      "    module = self._load()\n",
      "  File \"c:\\Users\\FRED031\\.conda\\envs\\tf-gpu\\lib\\site-packages\\tensorflow\\__init__.py\", line 44, in _load\n",
      "    module = _importlib.import_module(self.__name__)\n",
      "  File \"c:\\Users\\FRED031\\.conda\\envs\\tf-gpu\\lib\\importlib\\__init__.py\", line 127, in import_module\n",
      "    return _bootstrap._gcd_import(name[level:], package, level)\n",
      "  File \"<frozen importlib._bootstrap>\", line 1006, in _gcd_import\n",
      "  File \"<frozen importlib._bootstrap>\", line 983, in _find_and_load\n",
      "  File \"<frozen importlib._bootstrap>\", line 965, in _find_and_load_unlocked\n",
      "ModuleNotFoundError: No module named 'tensorflow_core.estimator'\n",
      "Traceback (most recent call last):\n",
      "  File \"c:\\Users\\FRED031\\.conda\\envs\\tf-gpu\\lib\\site-packages\\IPython\\core\\interactiveshell.py\", line 3552, in run_code\n",
      "    exec(code_obj, self.user_global_ns, self.user_ns)\n",
      "  File \"C:\\Users\\FRED031\\AppData\\Local\\Temp\\ipykernel_22632\\2531087222.py\", line 9, in <module>\n",
      "    import matplotlib.pyplot as plt\n",
      "ModuleNotFoundError: No module named 'matplotlib'\n",
      "\n",
      "During handling of the above exception, another exception occurred:\n",
      "\n",
      "Traceback (most recent call last):\n",
      "  File \"c:\\Users\\FRED031\\.conda\\envs\\tf-gpu\\lib\\site-packages\\IPython\\core\\interactiveshell.py\", line 2098, in showtraceback\n",
      "    stb = value._render_traceback_()\n",
      "AttributeError: 'ModuleNotFoundError' object has no attribute '_render_traceback_'\n",
      "\n",
      "During handling of the above exception, another exception occurred:\n",
      "\n",
      "Traceback (most recent call last):\n",
      "  File \"c:\\Users\\FRED031\\.conda\\envs\\tf-gpu\\lib\\site-packages\\IPython\\core\\interactiveshell.py\", line 3472, in run_ast_nodes\n",
      "    if (await self.run_code(code, result,  async_=asy)):\n",
      "  File \"c:\\Users\\FRED031\\.conda\\envs\\tf-gpu\\lib\\site-packages\\IPython\\core\\interactiveshell.py\", line 3569, in run_code\n",
      "    self.showtraceback(running_compiled_code=True)\n",
      "  File \"c:\\Users\\FRED031\\.conda\\envs\\tf-gpu\\lib\\site-packages\\IPython\\core\\interactiveshell.py\", line 2101, in showtraceback\n",
      "    value, tb, tb_offset=tb_offset)\n",
      "  File \"c:\\Users\\FRED031\\.conda\\envs\\tf-gpu\\lib\\site-packages\\IPython\\core\\ultratb.py\", line 1368, in structured_traceback\n",
      "    self, etype, value, tb, tb_offset, number_of_lines_of_context)\n",
      "  File \"c:\\Users\\FRED031\\.conda\\envs\\tf-gpu\\lib\\site-packages\\IPython\\core\\ultratb.py\", line 1268, in structured_traceback\n",
      "    self, etype, value, tb, tb_offset, number_of_lines_of_context\n",
      "  File \"c:\\Users\\FRED031\\.conda\\envs\\tf-gpu\\lib\\site-packages\\IPython\\core\\ultratb.py\", line 1125, in structured_traceback\n",
      "    tb_offset)\n",
      "  File \"c:\\Users\\FRED031\\.conda\\envs\\tf-gpu\\lib\\site-packages\\IPython\\core\\ultratb.py\", line 1082, in format_exception_as_a_whole\n",
      "    last_unique, recursion_repeat = find_recursion(orig_etype, evalue, records)\n",
      "  File \"c:\\Users\\FRED031\\.conda\\envs\\tf-gpu\\lib\\site-packages\\IPython\\core\\ultratb.py\", line 382, in find_recursion\n",
      "    return len(records), 0\n",
      "TypeError: object of type 'NoneType' has no len()\n",
      "\n",
      "During handling of the above exception, another exception occurred:\n",
      "\n",
      "Traceback (most recent call last):\n",
      "  File \"c:\\Users\\FRED031\\.conda\\envs\\tf-gpu\\lib\\site-packages\\IPython\\core\\interactiveshell.py\", line 2098, in showtraceback\n",
      "    stb = value._render_traceback_()\n",
      "AttributeError: 'TypeError' object has no attribute '_render_traceback_'\n",
      "\n",
      "During handling of the above exception, another exception occurred:\n",
      "\n",
      "Traceback (most recent call last):\n",
      "  File \"c:\\Users\\FRED031\\.conda\\envs\\tf-gpu\\lib\\site-packages\\IPython\\core\\ultratb.py\", line 1101, in get_records\n",
      "    return _fixed_getinnerframes(etb, number_of_lines_of_context, tb_offset)\n",
      "  File \"c:\\Users\\FRED031\\.conda\\envs\\tf-gpu\\lib\\site-packages\\IPython\\core\\ultratb.py\", line 248, in wrapped\n",
      "    return f(*args, **kwargs)\n",
      "  File \"c:\\Users\\FRED031\\.conda\\envs\\tf-gpu\\lib\\site-packages\\IPython\\core\\ultratb.py\", line 281, in _fixed_getinnerframes\n",
      "    records = fix_frame_records_filenames(inspect.getinnerframes(etb, context))\n",
      "  File \"c:\\Users\\FRED031\\.conda\\envs\\tf-gpu\\lib\\inspect.py\", line 1502, in getinnerframes\n",
      "    frameinfo = (tb.tb_frame,) + getframeinfo(tb, context)\n",
      "  File \"c:\\Users\\FRED031\\.conda\\envs\\tf-gpu\\lib\\inspect.py\", line 1460, in getframeinfo\n",
      "    filename = getsourcefile(frame) or getfile(frame)\n",
      "  File \"c:\\Users\\FRED031\\.conda\\envs\\tf-gpu\\lib\\inspect.py\", line 696, in getsourcefile\n",
      "    if getattr(getmodule(object, filename), '__loader__', None) is not None:\n",
      "  File \"c:\\Users\\FRED031\\.conda\\envs\\tf-gpu\\lib\\inspect.py\", line 733, in getmodule\n",
      "    if ismodule(module) and hasattr(module, '__file__'):\n",
      "  File \"c:\\Users\\FRED031\\.conda\\envs\\tf-gpu\\lib\\site-packages\\tensorflow\\__init__.py\", line 50, in __getattr__\n",
      "    module = self._load()\n",
      "  File \"c:\\Users\\FRED031\\.conda\\envs\\tf-gpu\\lib\\site-packages\\tensorflow\\__init__.py\", line 44, in _load\n",
      "    module = _importlib.import_module(self.__name__)\n",
      "  File \"c:\\Users\\FRED031\\.conda\\envs\\tf-gpu\\lib\\importlib\\__init__.py\", line 127, in import_module\n",
      "    return _bootstrap._gcd_import(name[level:], package, level)\n",
      "  File \"<frozen importlib._bootstrap>\", line 1006, in _gcd_import\n",
      "  File \"<frozen importlib._bootstrap>\", line 983, in _find_and_load\n",
      "  File \"<frozen importlib._bootstrap>\", line 965, in _find_and_load_unlocked\n",
      "ModuleNotFoundError: No module named 'tensorflow_core.estimator'\n",
      "Traceback (most recent call last):\n",
      "  File \"c:\\Users\\FRED031\\.conda\\envs\\tf-gpu\\lib\\site-packages\\IPython\\core\\interactiveshell.py\", line 3552, in run_code\n",
      "    exec(code_obj, self.user_global_ns, self.user_ns)\n",
      "  File \"C:\\Users\\FRED031\\AppData\\Local\\Temp\\ipykernel_22632\\2531087222.py\", line 9, in <module>\n",
      "    import matplotlib.pyplot as plt\n",
      "ModuleNotFoundError: No module named 'matplotlib'\n",
      "\n",
      "During handling of the above exception, another exception occurred:\n",
      "\n",
      "Traceback (most recent call last):\n",
      "  File \"c:\\Users\\FRED031\\.conda\\envs\\tf-gpu\\lib\\site-packages\\IPython\\core\\interactiveshell.py\", line 2098, in showtraceback\n",
      "    stb = value._render_traceback_()\n",
      "AttributeError: 'ModuleNotFoundError' object has no attribute '_render_traceback_'\n",
      "\n",
      "During handling of the above exception, another exception occurred:\n",
      "\n",
      "Traceback (most recent call last):\n",
      "  File \"c:\\Users\\FRED031\\.conda\\envs\\tf-gpu\\lib\\site-packages\\IPython\\core\\interactiveshell.py\", line 3472, in run_ast_nodes\n",
      "    if (await self.run_code(code, result,  async_=asy)):\n",
      "  File \"c:\\Users\\FRED031\\.conda\\envs\\tf-gpu\\lib\\site-packages\\IPython\\core\\interactiveshell.py\", line 3569, in run_code\n",
      "    self.showtraceback(running_compiled_code=True)\n",
      "  File \"c:\\Users\\FRED031\\.conda\\envs\\tf-gpu\\lib\\site-packages\\IPython\\core\\interactiveshell.py\", line 2101, in showtraceback\n",
      "    value, tb, tb_offset=tb_offset)\n",
      "  File \"c:\\Users\\FRED031\\.conda\\envs\\tf-gpu\\lib\\site-packages\\IPython\\core\\ultratb.py\", line 1368, in structured_traceback\n",
      "    self, etype, value, tb, tb_offset, number_of_lines_of_context)\n",
      "  File \"c:\\Users\\FRED031\\.conda\\envs\\tf-gpu\\lib\\site-packages\\IPython\\core\\ultratb.py\", line 1268, in structured_traceback\n",
      "    self, etype, value, tb, tb_offset, number_of_lines_of_context\n",
      "  File \"c:\\Users\\FRED031\\.conda\\envs\\tf-gpu\\lib\\site-packages\\IPython\\core\\ultratb.py\", line 1125, in structured_traceback\n",
      "    tb_offset)\n",
      "  File \"c:\\Users\\FRED031\\.conda\\envs\\tf-gpu\\lib\\site-packages\\IPython\\core\\ultratb.py\", line 1082, in format_exception_as_a_whole\n",
      "    last_unique, recursion_repeat = find_recursion(orig_etype, evalue, records)\n",
      "  File \"c:\\Users\\FRED031\\.conda\\envs\\tf-gpu\\lib\\site-packages\\IPython\\core\\ultratb.py\", line 382, in find_recursion\n",
      "    return len(records), 0\n",
      "TypeError: object of type 'NoneType' has no len()\n",
      "\n",
      "During handling of the above exception, another exception occurred:\n",
      "\n",
      "Traceback (most recent call last):\n",
      "  File \"c:\\Users\\FRED031\\.conda\\envs\\tf-gpu\\lib\\site-packages\\IPython\\core\\interactiveshell.py\", line 2098, in showtraceback\n",
      "    stb = value._render_traceback_()\n",
      "AttributeError: 'TypeError' object has no attribute '_render_traceback_'\n",
      "\n",
      "During handling of the above exception, another exception occurred:\n",
      "\n",
      "Traceback (most recent call last):\n",
      "  File \"c:\\Users\\FRED031\\.conda\\envs\\tf-gpu\\lib\\site-packages\\IPython\\core\\interactiveshell.py\", line 3029, in _run_cell\n",
      "    return runner(coro)\n",
      "  File \"c:\\Users\\FRED031\\.conda\\envs\\tf-gpu\\lib\\site-packages\\IPython\\core\\async_helpers.py\", line 78, in _pseudo_sync_runner\n",
      "    coro.send(None)\n",
      "  File \"c:\\Users\\FRED031\\.conda\\envs\\tf-gpu\\lib\\site-packages\\IPython\\core\\interactiveshell.py\", line 3257, in run_cell_async\n",
      "    interactivity=interactivity, compiler=compiler, result=result)\n",
      "  File \"c:\\Users\\FRED031\\.conda\\envs\\tf-gpu\\lib\\site-packages\\IPython\\core\\interactiveshell.py\", line 3491, in run_ast_nodes\n",
      "    self.showtraceback()\n",
      "  File \"c:\\Users\\FRED031\\.conda\\envs\\tf-gpu\\lib\\site-packages\\IPython\\core\\interactiveshell.py\", line 2101, in showtraceback\n",
      "    value, tb, tb_offset=tb_offset)\n",
      "  File \"c:\\Users\\FRED031\\.conda\\envs\\tf-gpu\\lib\\site-packages\\IPython\\core\\ultratb.py\", line 1368, in structured_traceback\n",
      "    self, etype, value, tb, tb_offset, number_of_lines_of_context)\n",
      "  File \"c:\\Users\\FRED031\\.conda\\envs\\tf-gpu\\lib\\site-packages\\IPython\\core\\ultratb.py\", line 1268, in structured_traceback\n",
      "    self, etype, value, tb, tb_offset, number_of_lines_of_context\n",
      "  File \"c:\\Users\\FRED031\\.conda\\envs\\tf-gpu\\lib\\site-packages\\IPython\\core\\ultratb.py\", line 1143, in structured_traceback\n",
      "    chained_exceptions_tb_offset)\n",
      "  File \"c:\\Users\\FRED031\\.conda\\envs\\tf-gpu\\lib\\site-packages\\IPython\\core\\ultratb.py\", line 1082, in format_exception_as_a_whole\n",
      "    last_unique, recursion_repeat = find_recursion(orig_etype, evalue, records)\n",
      "  File \"c:\\Users\\FRED031\\.conda\\envs\\tf-gpu\\lib\\site-packages\\IPython\\core\\ultratb.py\", line 382, in find_recursion\n",
      "    return len(records), 0\n",
      "TypeError: object of type 'NoneType' has no len()\n",
      "\n",
      "During handling of the above exception, another exception occurred:\n",
      "\n",
      "Traceback (most recent call last):\n",
      "  File \"c:\\Users\\FRED031\\.conda\\envs\\tf-gpu\\lib\\site-packages\\IPython\\core\\interactiveshell.py\", line 2098, in showtraceback\n",
      "    stb = value._render_traceback_()\n",
      "AttributeError: 'TypeError' object has no attribute '_render_traceback_'\n",
      "\n",
      "During handling of the above exception, another exception occurred:\n",
      "\n",
      "Traceback (most recent call last):\n",
      "  File \"c:\\Users\\FRED031\\.conda\\envs\\tf-gpu\\lib\\site-packages\\IPython\\core\\ultratb.py\", line 1101, in get_records\n",
      "    return _fixed_getinnerframes(etb, number_of_lines_of_context, tb_offset)\n",
      "  File \"c:\\Users\\FRED031\\.conda\\envs\\tf-gpu\\lib\\site-packages\\IPython\\core\\ultratb.py\", line 248, in wrapped\n",
      "    return f(*args, **kwargs)\n",
      "  File \"c:\\Users\\FRED031\\.conda\\envs\\tf-gpu\\lib\\site-packages\\IPython\\core\\ultratb.py\", line 281, in _fixed_getinnerframes\n",
      "    records = fix_frame_records_filenames(inspect.getinnerframes(etb, context))\n",
      "  File \"c:\\Users\\FRED031\\.conda\\envs\\tf-gpu\\lib\\inspect.py\", line 1502, in getinnerframes\n",
      "    frameinfo = (tb.tb_frame,) + getframeinfo(tb, context)\n",
      "  File \"c:\\Users\\FRED031\\.conda\\envs\\tf-gpu\\lib\\inspect.py\", line 1460, in getframeinfo\n",
      "    filename = getsourcefile(frame) or getfile(frame)\n",
      "  File \"c:\\Users\\FRED031\\.conda\\envs\\tf-gpu\\lib\\inspect.py\", line 696, in getsourcefile\n",
      "    if getattr(getmodule(object, filename), '__loader__', None) is not None:\n",
      "  File \"c:\\Users\\FRED031\\.conda\\envs\\tf-gpu\\lib\\inspect.py\", line 733, in getmodule\n",
      "    if ismodule(module) and hasattr(module, '__file__'):\n",
      "  File \"c:\\Users\\FRED031\\.conda\\envs\\tf-gpu\\lib\\site-packages\\tensorflow\\__init__.py\", line 50, in __getattr__\n",
      "    module = self._load()\n",
      "  File \"c:\\Users\\FRED031\\.conda\\envs\\tf-gpu\\lib\\site-packages\\tensorflow\\__init__.py\", line 44, in _load\n",
      "    module = _importlib.import_module(self.__name__)\n",
      "  File \"c:\\Users\\FRED031\\.conda\\envs\\tf-gpu\\lib\\importlib\\__init__.py\", line 127, in import_module\n",
      "    return _bootstrap._gcd_import(name[level:], package, level)\n",
      "  File \"<frozen importlib._bootstrap>\", line 1006, in _gcd_import\n",
      "  File \"<frozen importlib._bootstrap>\", line 983, in _find_and_load\n",
      "  File \"<frozen importlib._bootstrap>\", line 965, in _find_and_load_unlocked\n",
      "ModuleNotFoundError: No module named 'tensorflow_core.estimator'\n"
     ]
    }
   ],
   "source": [
    "# from tensorflow import keras\n",
    "import tensorflow as tf\n",
    "#from model_architectures.lenet import lenet\n",
    "#import model_architectures.lenet\n",
    "from lenet import lenet\n",
    "\n",
    "# Helper libraries\n",
    "import numpy as np\n",
    "import matplotlib.pyplot as plt\n",
    "\n",
    "print(tf.__version__)"
   ]
  },
  {
   "cell_type": "code",
   "execution_count": null,
   "metadata": {},
   "outputs": [],
   "source": [
    "print(\"Num GPUs Available: \", len(tf.config.list_physical_devices('GPU')))"
   ]
  },
  {
   "cell_type": "code",
   "execution_count": null,
   "metadata": {},
   "outputs": [],
   "source": [
    "(train_images, train_labels), (test_images, test_labels) = keras.datasets.fashion_mnist.load_data()\n",
    "\n",
    "# Scale images\n",
    "train_images = train_images / 255.0\n",
    "\n",
    "test_images = test_images / 255.0\n",
    "\n",
    "train_images.shape"
   ]
  },
  {
   "cell_type": "code",
   "execution_count": null,
   "metadata": {},
   "outputs": [],
   "source": [
    "mod = lenet((28, 28, 1), 10)"
   ]
  },
  {
   "cell_type": "code",
   "execution_count": null,
   "metadata": {},
   "outputs": [],
   "source": [
    "mod.summary()"
   ]
  },
  {
   "cell_type": "code",
   "execution_count": null,
   "metadata": {},
   "outputs": [],
   "source": [
    "mod.compile(optimizer='adam',\n",
    "              loss=tf.keras.losses.SparseCategoricalCrossentropy(from_logits=True),\n",
    "              metrics=['accuracy'])"
   ]
  },
  {
   "cell_type": "code",
   "execution_count": null,
   "metadata": {},
   "outputs": [],
   "source": [
    "mod.fit(train_images, train_labels, epochs=50, batch_size=16)"
   ]
  },
  {
   "cell_type": "code",
   "execution_count": null,
   "metadata": {},
   "outputs": [],
   "source": [
    "mod.evaluate(test_images, test_labels)"
   ]
  }
 ],
 "metadata": {
  "kernelspec": {
   "display_name": "Python 3.7.13 ('tf-gpu')",
   "language": "python",
   "name": "python3"
  },
  "language_info": {
   "codemirror_mode": {
    "name": "ipython",
    "version": 3
   },
   "file_extension": ".py",
   "mimetype": "text/x-python",
   "name": "python",
   "nbconvert_exporter": "python",
   "pygments_lexer": "ipython3",
   "version": "3.7.13"
  },
  "orig_nbformat": 4,
  "vscode": {
   "interpreter": {
    "hash": "08286ed1c6d9ea3bb50fd3ad06de465f13e5fb81bdf1a2b8d47835827067954d"
   }
  }
 },
 "nbformat": 4,
 "nbformat_minor": 2
}
